try {
    console.log("Inicio");
    let suma = 15 + 13;
    console.log("El resultado es " + suma);
} catch (error) {
    console.log("Se ignora el catch porque no hay errores"); 
}

try {
    console.log("Inicio");
    let suma = 15 + 13;
    console.log("El resultado es " + resultado);
} catch (error) {
    console.log("Hay un error! " + error); 
}